*Что вы думаете? Выполнится ли .catch? Поясните свой ответ.*

>new Promise(function(resolve, reject) {
setTimeout(() => {
throw new Error("Whoops!");
}, 1000);
}).catch(alert);
> 

**ОТВЕТ**

нет, так как ошибка генерируется через определенное время, но не сразу, поэтому и не попадает в catch